tensor(7209)
1024
Exception ignored in: <function _releaseLock at 0x7fb75ab83d90>
Traceback (most recent call last):
  File "/usr/lib/python3.10/logging/__init__.py", line 228, in _releaseLock
    def _releaseLock():
KeyboardInterrupt:
Traceback (most recent call last):
  File "/home/kaustubh/llm/lib/python3.10/site-packages/torch/utils/data/dataloader.py", line 1132, in _try_get_data
    data = self._data_queue.get(timeout=timeout)
  File "/usr/lib/python3.10/multiprocessing/queues.py", line 114, in get
    raise Empty
_queue.Empty
The above exception was the direct cause of the following exception:
Traceback (most recent call last):
  File "/home/kaustubh/Code3/Forrest Cover Type/cov_tester_2.py", line 144, in <module>
    main(data_path=data_path,batch_size=batch_size,num_epochs=num_epochs,learning_rate=learning_rate,model_path=model_path)
  File "/home/kaustubh/Code3/Forrest Cover Type/cov_tester_2.py", line 139, in main
    train_emb(model, train_emb_loader, criterion, optimizer, num_epochs=num_epochs,device=torch.device('cuda'),test_loader = test_emb_loader,test_total_loader = None)
  File "/home/kaustubh/Code3/Forrest Cover Type/cov_help.py", line 417, in train_emb
    for i, data in enumerate(train_loader, 0):
  File "/home/kaustubh/llm/lib/python3.10/site-packages/torch/utils/data/dataloader.py", line 633, in __next__
    data = self._next_data()
  File "/home/kaustubh/llm/lib/python3.10/site-packages/torch/utils/data/dataloader.py", line 1328, in _next_data
    idx, data = self._get_data()
  File "/home/kaustubh/llm/lib/python3.10/site-packages/torch/utils/data/dataloader.py", line 1294, in _get_data
    success, data = self._try_get_data()
  File "/home/kaustubh/llm/lib/python3.10/site-packages/torch/utils/data/dataloader.py", line 1145, in _try_get_data
    raise RuntimeError('DataLoader worker (pid(s) {}) exited unexpectedly'.format(pids_str)) from e
RuntimeError: DataLoader worker (pid(s) 3609346) exited unexpectedly