tensor(2551)
256
Exception ignored in: <function _releaseLock at 0x7f6d1bb87d00>
Traceback (most recent call last):
  File "/usr/lib/python3.10/logging/__init__.py", line 228, in _releaseLock
    def _releaseLock():
KeyboardInterrupt:
Traceback (most recent call last):
  File "/home/kaustubh/llm/lib/python3.10/site-packages/torch/utils/data/dataloader.py", line 1133, in _try_get_data
    data = self._data_queue.get(timeout=timeout)
  File "/usr/lib/python3.10/multiprocessing/queues.py", line 114, in get
    raise Empty
_queue.Empty
The above exception was the direct cause of the following exception:
Traceback (most recent call last):
  File "/home/kaustubh/Code3/Churn /churn_tester.py", line 151, in <module>
    main(data_path=data_path,batch_size=batch_size,num_epochs=num_epochs,learning_rate=learning_rate,model_path=model_path)
  File "/home/kaustubh/Code3/Churn /churn_tester.py", line 144, in main
    train_emb(model, train_emb_loader, criterion, optimizer, num_epochs=num_epochs,device=torch.device('cuda'),test_loader = test_emb_loader,test_total_loader = None)
  File "/home/kaustubh/Code3/Churn /churn_help.py", line 380, in train_emb
    for i, data in enumerate(train_loader, 0):
  File "/home/kaustubh/llm/lib/python3.10/site-packages/torch/utils/data/dataloader.py", line 631, in __next__
    data = self._next_data()
  File "/home/kaustubh/llm/lib/python3.10/site-packages/torch/utils/data/dataloader.py", line 1329, in _next_data
    idx, data = self._get_data()
  File "/home/kaustubh/llm/lib/python3.10/site-packages/torch/utils/data/dataloader.py", line 1295, in _get_data
    success, data = self._try_get_data()
  File "/home/kaustubh/llm/lib/python3.10/site-packages/torch/utils/data/dataloader.py", line 1146, in _try_get_data
    raise RuntimeError(f'DataLoader worker (pid(s) {pids_str}) exited unexpectedly') from e
RuntimeError: DataLoader worker (pid(s) 1978628) exited unexpectedly