Traceback (most recent call last):
  File "/home/kaustubh/Code3/Churn /churn_trainer.py", line 102, in <module>
    main(data_path=data_path,batch_size=batch_size,num_epochs=num_epochs,learning_rate=learning_rate,train_flag=train_flag)
  File "/home/kaustubh/Code3/Churn /churn_trainer.py", line 54, in main
    X,Y = churn_data_loader(data_path,norm=norm)
  File "/home/kaustubh/Code3/Churn /churn_help.py", line 137, in churn_data_loader
    Y = df.loc[:, ['Exited']].replace(dict(yes=True, no=False))
  File "/home/kaustubh/llm/lib/python3.10/site-packages/pandas/core/indexing.py", line 1147, in __getitem__
    return self._getitem_tuple(key)
  File "/home/kaustubh/llm/lib/python3.10/site-packages/pandas/core/indexing.py", line 1339, in _getitem_tuple
    return self._getitem_tuple_same_dim(tup)
  File "/home/kaustubh/llm/lib/python3.10/site-packages/pandas/core/indexing.py", line 994, in _getitem_tuple_same_dim
    retval = getattr(retval, self.name)._getitem_axis(key, axis=i)
  File "/home/kaustubh/llm/lib/python3.10/site-packages/pandas/core/indexing.py", line 1382, in _getitem_axis
    return self._getitem_iterable(key, axis=axis)
  File "/home/kaustubh/llm/lib/python3.10/site-packages/pandas/core/indexing.py", line 1322, in _getitem_iterable
    keyarr, indexer = self._get_listlike_indexer(key, axis)
  File "/home/kaustubh/llm/lib/python3.10/site-packages/pandas/core/indexing.py", line 1520, in _get_listlike_indexer
    keyarr, indexer = ax._get_indexer_strict(key, axis_name)
  File "/home/kaustubh/llm/lib/python3.10/site-packages/pandas/core/indexes/base.py", line 6114, in _get_indexer_strict
    self._raise_if_missing(keyarr, indexer, axis_name)
  File "/home/kaustubh/llm/lib/python3.10/site-packages/pandas/core/indexes/base.py", line 6175, in _raise_if_missing
    raise KeyError(f"None of [{key}] are in the [{axis_name}]")
KeyError: "None of [Index(['Exited'], dtype='object')] are in the [columns]"